<?xml version="1.0" ?>
<robot name="urdf_base" xmlns:xacro="http://www.ros.org/wiki/xacro">

<xacro:include filename="$(find server_bot)/urdf/materials.xacro" />
<xacro:include filename="$(find server_bot)/urdf/urdf_base.trans" />
<xacro:include filename="$(find server_bot)/urdf/urdf_base.gazebo" />
<link name="base_footprint"/>

<joint name="footprint_link_joint" type="fixed">
  <origin xyz="0 0 0" rpy="0 0 0"/>
  <parent link="base_footprint"/>
  <child link="base_link"/>
  <axis xyz="0 0 0"/>
</joint>
  
<link name="base_link">
  <inertial>
    <origin xyz="-0.017964706437151683 7.958078640513123e-15 0.19692457662763105" rpy="0 0 0"/>
    <mass value="19.185824620104434"/>
    <inertia ixx="1.663084" iyy="1.844906" izz="1.439572" ixy="-0.0" iyz="0.0" ixz="0.192956"/>
  </inertial>
  <visual>
    <origin xyz="0 0 0" rpy="0 0 0"/>
    <geometry>
      <mesh filename="package://server_bot/meshes/base_link.stl" scale="0.001 0.001 0.001"/>
    </geometry>
    <material name="silver"/>
  </visual>
  <collision>
    <origin xyz="0 0 0" rpy="0 0 0"/>
    <geometry>
      <mesh filename="package://server_bot/meshes/base_link.stl" scale="0.001 0.001 0.001"/>
    </geometry>
  </collision>
</link>



<link name="wheel_1_1">
  <inertial>
    <origin xyz="0.013000187336528163 3.3163871071550943e-07 4.379836845702645e-07" rpy="0 0 0"/>
    <mass value="1.6029976514941926"/>
    <inertia ixx="0.002004" iyy="0.001092" izz="0.001092" ixy="0.0" iyz="-0.0" ixz="0.0"/>
  </inertial>
  <visual>
    <origin xyz="0.18941 0.509146 -0.056794" rpy="0 0 0"/>
    <geometry>
      <mesh filename="package://server_bot/meshes/wheel_1_1.stl" scale="0.001 0.001 0.001"/>
    </geometry>
    <material name="silver"/>
  </visual>
  <collision>
    <origin xyz="0.18941 0.509146 -0.056794" rpy="0 0 0"/>
    <geometry>
      <mesh filename="package://server_bot/meshes/wheel_1_1.stl" scale="0.001 0.001 0.001"/>
    </geometry>
  </collision>
</link>

<link name="wheel_2_1">
  <inertial>
    <origin xyz="0.013000187336532881 3.3163871146491e-07 4.379836929663261e-07" rpy="0 0 0"/>
    <mass value="1.6029976514941917"/>
    <inertia ixx="0.002004" iyy="0.001092" izz="0.001092" ixy="-0.0" iyz="-0.0" ixz="-0.0"/>
  </inertial>
  <visual>
    <origin xyz="0.18941 0.129146 -0.056794" rpy="0 0 0"/>
    <geometry>
      <mesh filename="package://server_bot/meshes/wheel_2_1.stl" scale="0.001 0.001 0.001"/>
    </geometry>
    <material name="silver"/>
  </visual>
  <collision>
    <origin xyz="0.18941 0.129146 -0.056794" rpy="0 0 0"/>
    <geometry>
      <mesh filename="package://server_bot/meshes/wheel_2_1.stl" scale="0.001 0.001 0.001"/>
    </geometry>
  </collision>
</link>

<link name="wheel_4_1">
  <inertial>
    <origin xyz="-0.012999812663476495 3.316387161000911e-07 4.379836937781767e-07" rpy="0 0 0"/>
    <mass value="1.6029976514941915"/>
    <inertia ixx="0.002004" iyy="0.001092" izz="0.001092" ixy="0.0" iyz="-0.0" ixz="0.0"/>
  </inertial>
  <visual>
    <origin xyz="0.54941 0.129146 -0.056794" rpy="0 0 0"/>
    <geometry>
      <mesh filename="package://server_bot/meshes/wheel_4_1.stl" scale="0.001 0.001 0.001"/>
    </geometry>
    <material name="silver"/>
  </visual>
  <collision>
    <origin xyz="0.54941 0.129146 -0.056794" rpy="0 0 0"/>
    <geometry>
      <mesh filename="package://server_bot/meshes/wheel_4_1.stl" scale="0.001 0.001 0.001"/>
    </geometry>
  </collision>
</link>

<link name="wheel_3_1">
  <inertial>
    <origin xyz="-0.012999812663473054 3.316387148233346e-07 4.379836854931374e-07" rpy="0 0 0"/>
    <mass value="1.6029976514941926"/>
    <inertia ixx="0.002004" iyy="0.001092" izz="0.001092" ixy="0.0" iyz="0.0" ixz="0.0"/>
  </inertial>
  <visual>
    <origin xyz="0.54941 0.509146 -0.056794" rpy="0 0 0"/>
    <geometry>
      <mesh filename="package://server_bot/meshes/wheel_3_1.stl" scale="0.001 0.001 0.001"/>
    </geometry>
    <material name="silver"/>
  </visual>
  <collision>
    <origin xyz="0.54941 0.509146 -0.056794" rpy="0 0 0"/>
    <geometry>
      <mesh filename="package://server_bot/meshes/wheel_3_1.stl" scale="0.001 0.001 0.001"/>
    </geometry>
  </collision>
</link>

<link name="camera">
    <inertial>
            <mass value="0.1" />
            <inertia ixx="0.01" ixy="0.0" ixz="0"
            iyy="0.01" iyz="0" izz="0.01" />
    </inertial>

    <visual>          
      <geometry>
        <box size="0.05 0.05 0.025"/>
      </geometry>
      <material name="white">
        <color rgba="1 1 1 1"/>
      </material>
    </visual>

    <collision>
      <geometry>
          <box size="0.05 0.05 0.025"/>
      </geometry>
    </collision>
</link>

<link name="lidar">
    <inertial>
            <mass value="0.5" />
            <inertia ixx="0.01" ixy="0.0" ixz="0"
            iyy="0.01" iyz="0" izz="0.01" />
    </inertial>

    <visual>          
      <geometry>
        <cylinder radius="0.025" length="0.015"/>
      </geometry>
      <material name="white">
        <color rgba="1 1 1 1"/>
      </material>
    </visual>

    <collision>
      <geometry>
          <box size="0.1 0.1 0.1"/>
      </geometry>
    </collision>
</link>

<link name="imu_link">
    <inertial>
      <mass value="0.3"/>
      <inertia ixx="0.01" ixy="0.0" ixz="0"
          iyy="0.01" iyz="0" izz="0.01" />
    </inertial>
    <visual>
      <geometry>
        <box size="0.05 0.05 0.05"/>
      </geometry>
      <material name="white">
        <color rgba="1 1 1 1"/>
      </material>
    </visual>
    <collision>
      <geometry>
          <box size="0.01 0.01 0.005"/>
      </geometry>
    </collision>
  
</link>
    




<joint name="Revolute 13" type="continuous">
  <origin xyz="-0.18941 -0.509146 0.056794" rpy="0 0 0"/>
  <parent link="base_link"/>
  <child link="wheel_1_1"/>
  <axis xyz="1.0 -0.0 0.0"/>
</joint>

<joint name="Revolute 14" type="continuous">
  <origin xyz="-0.18941 -0.129146 0.056794" rpy="0 0 0"/>
  <parent link="base_link"/>
  <child link="wheel_2_1"/>
  <axis xyz="1.0 -0.0 0.0"/>
</joint>

<joint name="Revolute 15" type="continuous">
  <origin xyz="-0.54941 -0.129146 0.056794" rpy="0 0 0"/>
  <parent link="base_link"/>
  <child link="wheel_4_1"/>
  <axis xyz="1.0 0.0 -0.0"/>
</joint>

<joint name="Revolute 16" type="continuous">
  <origin xyz="-0.54941 -0.509146 0.056794" rpy="0 0 0"/>
  <parent link="base_link"/>
  <child link="wheel_3_1"/>
  <axis xyz="1.0 0.0 -0.0"/>
</joint>

<joint name="camera_joint" type="fixed">
    <origin xyz="-0.35 -0.616 0.54" rpy="0 0.0 4.71"/>
    <parent link="base_link"/>
    <child link="camera"/>
    <axis xyz="0.0 0.0 1.0"/>    
</joint>

<joint name="lidar_joint" type="fixed">
  <origin xyz="-0.385 -0.61 0.080" rpy="0 0.0 3.14"/>
  <parent link="base_link"/>
  <child link="lidar"/>
  <axis xyz="0.0 0.0 1.0"/>
</joint>

<joint name="imu_joint" type="fixed">
  <origin xyz="-0.33 -0.31 0.08"/>
  <parent link="base_link"/>
  <child link="imu_link"/>
  <axis xyz="0.0 0.0 1.0"/>
</joint>

<gazebo reference="lidar">
    <material>Gazebo/Blue</material>
</gazebo>

<gazebo reference="camera">
    <material>Gazebo/Red</material>
</gazebo>

<gazebo reference="camera">
  <sensor type="camera" name="camera1">
    <visualize>true</visualize>
    <update_rate>30.0</update_rate>
    <camera name="head">
      <horizontal_fov>1.3962634</horizontal_fov>
      <image>
        <width>800</width>
        <height>800</height>
        <format>R8G8B8</format>
      </image>
      <clip>
        <near>0.02</near>
        <far>300</far>
      </clip>
    </camera>
    <plugin name="camera_controller" filename="libgazebo_ros_camera.so">
      <alwaysOn>true</alwaysOn>
      <updateRate>60.0</updateRate>
      <cameraName>/camera1</cameraName>
      <imageTopicName>image_raw</imageTopicName>
      <cameraInfoTopicName>info_camera</cameraInfoTopicName>
      <frameName>camera</frameName>1.57
      <hackBaseline>0.07</hackBaseline>
    </plugin>
  </sensor>
</gazebo>

<gazebo reference="lidar">
  <sensor type="ray" name="head_hokuyo_sensor">
    <pose>0 0 0 0 0 0</pose>
    <visualize>true</visualize>
    <update_rate>20</update_rate>
    <topic_name>lidar_topic</topic_name>
    <output_type>sensor_msgs/LaserScan</output_type>
    <ray>
      <scan>
        <horizontal>
          <samples>720</samples>
          <resolution>1</resolution>
          <min_angle>0</min_angle>
          <max_angle>6.28</max_angle>
        </horizontal>
      </scan>
      <range>
        <min>0.6</min>
        <max>3.5</max>
        <resolution>0.01</resolution>
      </range>
      <noise>
        <type>gaussian</type>
        <!--Noise parameters based on published spec for Hokuyo laser
              achieving "+-30mm" accuracy at range < 10m.  A mean of 0.0m and
              stddev of 0.01m will put 99.7% of samples within 0.03m of the true
              reading.-->
        <mean>0.0</mean>
        <stddev>0.01</stddev>
      </noise>
    </ray>
    <plugin name="gazebo_ros_head_hokuyo_controller" filename="libgazebo_ros_laser.so">
      <topicName>lidar_topic</topicName>
      <frameName>lidar</frameName>
    </plugin>
  </sensor>
</gazebo>

<gazebo>
  <plugin name="skid_steer_drive_controller" filename="libgazebo_ros_skid_steer_drive.so">
    <updateRate>15.0</updateRate>
    <robotNamespace>/</robotNamespace>
    <leftFrontJoint>Revolute 16</leftFrontJoint>
    <rightFrontJoint>Revolute 13</rightFrontJoint>
    <leftRearJoint>Revolute 15</leftRearJoint>
    <rightRearJoint>Revolute 14</rightRearJoint>
    <wheelSeparation>0.4</wheelSeparation>
    <wheelDiameter>0.215</wheelDiameter>
    <odometryFrame>odom</odometryFrame>
    <robotBaseFrame>base_link</robotBaseFrame>
    <publishOdom>true</publishOdom>
    <publishOdomTF>true</publishOdomTF>
    <publishWheelTF>true</publishWheelTF>
    <torque>20</torque>
    <topicName>cmd_vel</topicName>
    <publishTF>false</publishTF>
    <odometrySource>wheels</odometrySource>
  </plugin>
</gazebo>

<gazebo reference="imu_link">
  <gravity>true</gravity>
  <sensor name="imu_sensor" type="imu">
  <imu>
      <angular_velocity>
        <x>
          <noise type="gaussian">
            <mean>0.0</mean>
            <stddev>2e-4</stddev>
            <bias_mean>0.0000075</bias_mean>
            <bias_stddev>0.0000008</bias_stddev>
          </noise>
        </x>
        <y>
          <noise type="gaussian">
            <mean>0.0</mean>
            <stddev>2e-4</stddev>
            <bias_mean>0.0000075</bias_mean>
            <bias_stddev>0.0000008</bias_stddev>
          </noise>
        </y>
        <z>
          <noise type="gaussian">
            <mean>0.0</mean>
            <stddev>2e-4</stddev>
            <bias_mean>0.0000075</bias_mean>
            <bias_stddev>0.0000008</bias_stddev>
          </noise>
        </z>
      </angular_velocity>
      <linear_acceleration>
        <x>
          <noise type="gaussian">
            <mean>0.0</mean>
            <stddev>1.7e-2</stddev>
            <bias_mean>0.1</bias_mean>
            <bias_stddev>0.001</bias_stddev>
          </noise>
        </x>
        <y>
          <noise type="gaussian">
            <mean>0.0</mean>
            <stddev>1.7e-2</stddev>
            <bias_mean>0.1</bias_mean>
            <bias_stddev>0.001</bias_stddev>
          </noise>
        </y>
        <z>
          <noise type="gaussian">
            <mean>0.0</mean>
            <stddev>1.7e-2</stddev>
            <bias_mean>0.1</bias_mean>
            <bias_stddev>0.001</bias_stddev>
          </noise>
        </z>
      </linear_acceleration>
    </imu> 
<always_on>true</always_on>
    <update_rate>100</update_rate>
    <visualize>true</visualize>
    <topic>imu</topic>
    <plugin filename="libgazebo_ros_imu_sensor.so" name="imu_plugin">
      <topicName>imu</topicName>
      <bodyName>imu_link</bodyName>
      <updateRateHZ>20</updateRateHZ>
      <gaussianNoise>0.0</gaussianNoise>
      <xyzOffset>0 0 0</xyzOffset>
      <rpyOffset>0 0 0</rpyOffset>
      <frameName>imu_link</frameName>
      <initial_orientation_as_reference>true</initial_orientation_as_reference>
    </plugin>
    <pose>0 0 0 0 0 0</pose>
  </sensor>
</gazebo>
</robot>
