<sdf version='1.7'>
  <world name='default'>
    <model name='ground_plane'>
      <static>1</static>
      <link name='link'>
        <collision name='collision'>
          <geometry>
            <plane>
              <normal>0 0 1</normal>
              <size>100 100</size>
            </plane>
          </geometry>
          <surface>
            <contact>
              <collide_bitmask>65535</collide_bitmask>
              <ode/>
            </contact>
            <friction>
              <ode>
                <mu>100</mu>
                <mu2>50</mu2>
              </ode>
              <torsional>
                <ode/>
              </torsional>
            </friction>
            <bounce/>
          </surface>
          <max_contacts>10</max_contacts>
        </collision>
        <visual name='visual'>
          <cast_shadows>0</cast_shadows>
          <geometry>
            <plane>
              <normal>0 0 1</normal>
              <size>100 100</size>
            </plane>
          </geometry>
          <material>
            <script>
              <uri>file://media/materials/scripts/gazebo.material</uri>
              <name>Gazebo/Grey</name>
            </script>
          </material>
        </visual>
        <self_collide>0</self_collide>
        <enable_wind>0</enable_wind>
        <kinematic>0</kinematic>
      </link>
    </model>
    <light name='sun' type='directional'>
      <cast_shadows>1</cast_shadows>
      <pose>0 0 10 0 -0 0</pose>
      <diffuse>0.8 0.8 0.8 1</diffuse>
      <specular>0.2 0.2 0.2 1</specular>
      <attenuation>
        <range>1000</range>
        <constant>0.9</constant>
        <linear>0.01</linear>
        <quadratic>0.001</quadratic>
      </attenuation>
      <direction>-0.5 0.1 -0.9</direction>
      <spot>
        <inner_angle>0</inner_angle>
        <outer_angle>0</outer_angle>
        <falloff>0</falloff>
      </spot>
    </light>
    <scene>
      <shadows>0</shadows>
      <ambient>0.4 0.4 0.4 1</ambient>
      <background>0.7 0.7 0.7 1</background>
    </scene>
    <gui fullscreen='0'>
      <camera name='user_camera'>
        <pose>1.20119 -0.803048 19.5214 0 1.5138 0.009599</pose>
        <view_controller>orbit</view_controller>
        <projection_type>perspective</projection_type>
      </camera>
    </gui>
    <physics type='ode'>
      <real_time_update_rate>1000</real_time_update_rate>
      <max_step_size>0.001</max_step_size>
      <real_time_factor>1</real_time_factor>
      <ode>
        <solver>
          <type>quick</type>
          <iters>150</iters>
          <precon_iters>0</precon_iters>
          <sor>1.4</sor>
          <use_dynamic_moi_rescaling>1</use_dynamic_moi_rescaling>
        </solver>
        <constraints>
          <cfm>1e-05</cfm>
          <erp>0.2</erp>
          <contact_max_correcting_vel>2000</contact_max_correcting_vel>
          <contact_surface_layer>0.01</contact_surface_layer>
        </constraints>
      </ode>
    </physics>
    <model name='turtlebot_new_world'>
      <static>1</static>
      <frame name='ros_symbol::__model__' attached_to='ros_symbol::symbol'>
        <pose relative_to='__model__'>0 0 0 0 -0 0</pose>
      </frame>
      <static>1</static>
      <link name='ros_symbol::symbol'>
        <collision name='one_one'>
          <pose>-1.1 -1.1 0.25 0 -0 0</pose>
          <geometry>
            <cylinder>
              <radius>0.15</radius>
              <length>0.5</length>
            </cylinder>
          </geometry>
          <max_contacts>10</max_contacts>
          <surface>
            <bounce/>
            <friction>
              <ode/>
              <torsional>
                <ode/>
              </torsional>
            </friction>
            <contact>
              <ode/>
            </contact>
          </surface>
        </collision>
        <visual name='one_one'>
          <pose>-1.1 -1.1 0.25 0 -0 0</pose>
          <geometry>
            <cylinder>
              <radius>0.15</radius>
              <length>0.5</length>
            </cylinder>
          </geometry>
          <material>
            <script>
              <uri>file://media/materials/scripts/gazebo.material</uri>
              <name>Gazebo/White</name>
            </script>
          </material>
        </visual>
        <collision name='one_three'>
          <pose>-1.1 1.1 0.25 0 -0 0</pose>
          <geometry>
            <cylinder>
              <radius>0.15</radius>
              <length>0.5</length>
            </cylinder>
          </geometry>
          <max_contacts>10</max_contacts>
          <surface>
            <bounce/>
            <friction>
              <ode/>
              <torsional>
                <ode/>
              </torsional>
            </friction>
            <contact>
              <ode/>
            </contact>
          </surface>
        </collision>
        <visual name='one_three'>
          <pose>-1.1 1.1 0.25 0 -0 0</pose>
          <geometry>
            <cylinder>
              <radius>0.15</radius>
              <length>0.5</length>
            </cylinder>
          </geometry>
          <material>
            <script>
              <uri>file://media/materials/scripts/gazebo.material</uri>
              <name>Gazebo/White</name>
            </script>
          </material>
        </visual>
        <collision name='two_one'>
          <pose>0 -1.1 0.25 0 -0 0</pose>
          <geometry>
            <cylinder>
              <radius>0.15</radius>
              <length>0.5</length>
            </cylinder>
          </geometry>
          <max_contacts>10</max_contacts>
          <surface>
            <bounce/>
            <friction>
              <ode/>
              <torsional>
                <ode/>
              </torsional>
            </friction>
            <contact>
              <ode/>
            </contact>
          </surface>
        </collision>
        <visual name='two_one'>
          <pose>0 -1.1 0.25 0 -0 0</pose>
          <geometry>
            <cylinder>
              <radius>0.15</radius>
              <length>0.5</length>
            </cylinder>
          </geometry>
          <material>
            <script>
              <uri>file://media/materials/scripts/gazebo.material</uri>
              <name>Gazebo/White</name>
            </script>
          </material>
        </visual>
        <collision name='two_three'>
          <pose>0 1.1 0.25 0 -0 0</pose>
          <geometry>
            <cylinder>
              <radius>0.15</radius>
              <length>0.5</length>
            </cylinder>
          </geometry>
          <max_contacts>10</max_contacts>
          <surface>
            <bounce/>
            <friction>
              <ode/>
              <torsional>
                <ode/>
              </torsional>
            </friction>
            <contact>
              <ode/>
            </contact>
          </surface>
        </collision>
        <visual name='two_three'>
          <pose>0 1.1 0.25 0 -0 0</pose>
          <geometry>
            <cylinder>
              <radius>0.15</radius>
              <length>0.5</length>
            </cylinder>
          </geometry>
          <material>
            <script>
              <uri>file://media/materials/scripts/gazebo.material</uri>
              <name>Gazebo/White</name>
            </script>
          </material>
        </visual>
        <collision name='three_one'>
          <pose>1.1 -1.1 0.25 0 -0 0</pose>
          <geometry>
            <cylinder>
              <radius>0.15</radius>
              <length>0.5</length>
            </cylinder>
          </geometry>
          <max_contacts>10</max_contacts>
          <surface>
            <bounce/>
            <friction>
              <ode/>
              <torsional>
                <ode/>
              </torsional>
            </friction>
            <contact>
              <ode/>
            </contact>
          </surface>
        </collision>
        <visual name='three_one'>
          <pose>1.1 -1.1 0.25 0 -0 0</pose>
          <geometry>
            <cylinder>
              <radius>0.15</radius>
              <length>0.5</length>
            </cylinder>
          </geometry>
          <material>
            <script>
              <uri>file://media/materials/scripts/gazebo.material</uri>
              <name>Gazebo/White</name>
            </script>
          </material>
        </visual>
        <collision name='three_three'>
          <pose>1.1 1.1 0.25 0 -0 0</pose>
          <geometry>
            <cylinder>
              <radius>0.15</radius>
              <length>0.5</length>
            </cylinder>
          </geometry>
          <max_contacts>10</max_contacts>
          <surface>
            <bounce/>
            <friction>
              <ode/>
              <torsional>
                <ode/>
              </torsional>
            </friction>
            <contact>
              <ode/>
            </contact>
          </surface>
        </collision>
        <visual name='three_three'>
          <pose>1.1 1.1 0.25 0 -0 0</pose>
          <geometry>
            <cylinder>
              <radius>0.15</radius>
              <length>0.5</length>
            </cylinder>
          </geometry>
          <material>
            <script>
              <uri>file://media/materials/scripts/gazebo.material</uri>
              <name>Gazebo/White</name>
            </script>
          </material>
        </visual>
        <collision name='head'>
          <pose>3.5 0 -0.5 0 -0 0</pose>
          <geometry>
            <mesh>
              <uri>model://turtlebot3_world/meshes/hexagon.dae</uri>
              <scale>0.8 0.8 0.8</scale>
            </mesh>
          </geometry>
          <max_contacts>10</max_contacts>
          <surface>
            <bounce/>
            <friction>
              <ode/>
              <torsional>
                <ode/>
              </torsional>
            </friction>
            <contact>
              <ode/>
            </contact>
          </surface>
        </collision>
        <visual name='head'>
          <pose>3.5 0 -0.5 0 -0 0</pose>
          <geometry>
            <mesh>
              <uri>model://turtlebot3_world/meshes/hexagon.dae</uri>
              <scale>0.8 0.8 0.8</scale>
            </mesh>
          </geometry>
          <material>
            <script>
              <uri>file://media/materials/scripts/gazebo.material</uri>
              <name>Gazebo/Green</name>
            </script>
          </material>
        </visual>
        <collision name='left_hand'>
          <pose>1.8 2.7 0 0 -0 0</pose>
          <geometry>
            <mesh>
              <uri>model://turtlebot3_world/meshes/hexagon.dae</uri>
              <scale>0.55 0.55 0.55</scale>
            </mesh>
          </geometry>
          <max_contacts>10</max_contacts>
          <surface>
            <bounce/>
            <friction>
              <ode/>
              <torsional>
                <ode/>
              </torsional>
            </friction>
            <contact>
              <ode/>
            </contact>
          </surface>
        </collision>
        <visual name='left_hand'>
          <pose>1.8 2.7 0 0 -0 0</pose>
          <geometry>
            <mesh>
              <uri>model://turtlebot3_world/meshes/hexagon.dae</uri>
              <scale>0.55 0.55 0.55</scale>
            </mesh>
          </geometry>
          <material>
            <script>
              <uri>file://media/materials/scripts/gazebo.material</uri>
              <name>Gazebo/Green</name>
            </script>
          </material>
        </visual>
        <collision name='right_hand'>
          <pose>1.8 -2.7 0 0 -0 0</pose>
          <geometry>
            <mesh>
              <uri>model://turtlebot3_world/meshes/hexagon.dae</uri>
              <scale>0.55 0.55 0.55</scale>
            </mesh>
          </geometry>
          <max_contacts>10</max_contacts>
          <surface>
            <bounce/>
            <friction>
              <ode/>
              <torsional>
                <ode/>
              </torsional>
            </friction>
            <contact>
              <ode/>
            </contact>
          </surface>
        </collision>
        <visual name='right_hand'>
          <pose>1.8 -2.7 0 0 -0 0</pose>
          <geometry>
            <mesh>
              <uri>model://turtlebot3_world/meshes/hexagon.dae</uri>
              <scale>0.55 0.55 0.55</scale>
            </mesh>
          </geometry>
          <material>
            <script>
              <uri>file://media/materials/scripts/gazebo.material</uri>
              <name>Gazebo/Green</name>
            </script>
          </material>
        </visual>
        <collision name='left_foot'>
          <pose>-1.8 2.7 0 0 -0 0</pose>
          <geometry>
            <mesh>
              <uri>model://turtlebot3_world/meshes/hexagon.dae</uri>
              <scale>0.55 0.55 0.55</scale>
            </mesh>
          </geometry>
          <max_contacts>10</max_contacts>
          <surface>
            <bounce/>
            <friction>
              <ode/>
              <torsional>
                <ode/>
              </torsional>
            </friction>
            <contact>
              <ode/>
            </contact>
          </surface>
        </collision>
        <visual name='left_foot'>
          <pose>-1.8 2.7 0 0 -0 0</pose>
          <geometry>
            <mesh>
              <uri>model://turtlebot3_world/meshes/hexagon.dae</uri>
              <scale>0.55 0.55 0.55</scale>
            </mesh>
          </geometry>
          <material>
            <script>
              <uri>file://media/materials/scripts/gazebo.material</uri>
              <name>Gazebo/Green</name>
            </script>
          </material>
        </visual>
        <collision name='right_foot'>
          <pose>-1.8 -2.7 0 0 -0 0</pose>
          <geometry>
            <mesh>
              <uri>model://turtlebot3_world/meshes/hexagon.dae</uri>
              <scale>0.55 0.55 0.55</scale>
            </mesh>
          </geometry>
          <max_contacts>10</max_contacts>
          <surface>
            <bounce/>
            <friction>
              <ode/>
              <torsional>
                <ode/>
              </torsional>
            </friction>
            <contact>
              <ode/>
            </contact>
          </surface>
        </collision>
        <visual name='right_foot'>
          <pose>-1.8 -2.7 0 0 -0 0</pose>
          <geometry>
            <mesh>
              <uri>model://turtlebot3_world/meshes/hexagon.dae</uri>
              <scale>0.55 0.55 0.55</scale>
            </mesh>
          </geometry>
          <material>
            <script>
              <uri>file://media/materials/scripts/gazebo.material</uri>
              <name>Gazebo/Green</name>
            </script>
          </material>
        </visual>
        <collision name='body'>
          <pose>0 0 -0.3 0 0 -1.5708</pose>
          <geometry>
            <mesh>
              <uri>model://turtlebot3_world/meshes/wall.dae</uri>
              <scale>0.25 0.25 0.25</scale>
            </mesh>
          </geometry>
          <max_contacts>10</max_contacts>
          <surface>
            <bounce/>
            <friction>
              <ode/>
              <torsional>
                <ode/>
              </torsional>
            </friction>
            <contact>
              <ode/>
            </contact>
          </surface>
        </collision>
        <visual name='body'>
          <pose>0 0 -0.3 0 0 -1.5708</pose>
          <geometry>
            <mesh>
              <uri>model://turtlebot3_world/meshes/wall.dae</uri>
              <scale>0.25 0.25 0.25</scale>
            </mesh>
          </geometry>
          <material>
            <script>
              <uri>file://media/materials/scripts/gazebo.material</uri>
              <name>Gazebo/FlatBlack</name>
            </script>
          </material>
        </visual>
        <pose relative_to='ros_symbol::__model__'>0 0 0 0 -0 0</pose>
        <self_collide>0</self_collide>
        <enable_wind>0</enable_wind>
        <kinematic>0</kinematic>
      </link>
    </model>
    <gravity>0 0 -9.8</gravity>
    <magnetic_field>6e-06 2.3e-05 -4.2e-05</magnetic_field>
    <atmosphere type='adiabatic'/>
    <wind/>
    <spherical_coordinates>
      <surface_model>EARTH_WGS84</surface_model>
      <latitude_deg>0</latitude_deg>
      <longitude_deg>0</longitude_deg>
      <elevation>0</elevation>
      <heading_deg>0</heading_deg>
    </spherical_coordinates>
    <model name='urdf_base'>
      <link name='base_footprint'>
        <inertial>
          <pose>-0.008721 0 0.193851 0 -0 0</pose>
          <mass>20.0858</mass>
          <inertia>
            <ixx>1.7162</ixx>
            <ixy>1.41136e-15</ixy>
            <ixz>0.200443</ixz>
            <iyy>1.95059</iyy>
            <iyz>-4.69256e-16</iyz>
            <izz>1.52214</izz>
          </inertia>
        </inertial>
        <collision name='base_footprint_fixed_joint_lump__base_link_collision'>
          <pose>0 0 0 0 -0 0</pose>
          <geometry>
            <mesh>
              <scale>0.001 0.001 0.001</scale>
              <uri>/home/aravs2/catkin_ws/src/server_bot/meshes/base_link.stl</uri>
            </mesh>
          </geometry>
          <surface>
            <contact>
              <ode/>
            </contact>
            <friction>
              <ode>
                <mu>0.2</mu>
                <mu2>0.2</mu2>
              </ode>
              <torsional>
                <ode/>
              </torsional>
            </friction>
            <bounce/>
          </surface>
          <max_contacts>10</max_contacts>
        </collision>
        <collision name='base_footprint_fixed_joint_lump__camera_collision_1'>
          <pose>0.295 0 0.54 0 -0 0</pose>
          <geometry>
            <box>
              <size>0.05 0.05 0.025</size>
            </box>
          </geometry>
          <surface>
            <contact>
              <ode/>
            </contact>
            <friction>
              <ode/>
              <torsional>
                <ode/>
              </torsional>
            </friction>
            <bounce/>
          </surface>
          <max_contacts>10</max_contacts>
        </collision>
        <collision name='base_footprint_fixed_joint_lump__imu_link_collision_2'>
          <pose>0 0 0.08 0 -0 0</pose>
          <geometry>
            <box>
              <size>0.01 0.01 0.005</size>
            </box>
          </geometry>
          <surface>
            <contact>
              <ode/>
            </contact>
            <friction>
              <ode/>
              <torsional>
                <ode/>
              </torsional>
            </friction>
            <bounce/>
          </surface>
          <max_contacts>10</max_contacts>
        </collision>
        <collision name='base_footprint_fixed_joint_lump__lidar_collision_3'>
          <pose>0.28 0 0.075 0 0 -1.57</pose>
          <geometry>
            <box>
              <size>0.1 0.1 0.1</size>
            </box>
          </geometry>
          <surface>
            <contact>
              <ode/>
            </contact>
            <friction>
              <ode/>
              <torsional>
                <ode/>
              </torsional>
            </friction>
            <bounce/>
          </surface>
          <max_contacts>10</max_contacts>
        </collision>
        <visual name='base_footprint_fixed_joint_lump__base_link_visual'>
          <pose>0 0 0 0 -0 0</pose>
          <geometry>
            <mesh>
              <scale>0.001 0.001 0.001</scale>
              <uri>/home/aravs2/catkin_ws/src/server_bot/meshes/base_link.stl</uri>
            </mesh>
          </geometry>
          <material>
            <script>
              <name>Gazebo/Silver</name>
              <uri>file://media/materials/scripts/gazebo.material</uri>
            </script>
          </material>
        </visual>
        <visual name='base_footprint_fixed_joint_lump__camera_visual_1'>
          <pose>0.295 0 0.54 0 -0 0</pose>
          <geometry>
            <box>
              <size>0.05 0.05 0.025</size>
            </box>
          </geometry>
          <material>
            <script>
              <name>Gazebo/Red</name>
              <uri>file://media/materials/scripts/gazebo.material</uri>
            </script>
          </material>
        </visual>
        <visual name='base_footprint_fixed_joint_lump__imu_link_visual_2'>
          <pose>0 0 0.08 0 -0 0</pose>
          <geometry>
            <box>
              <size>0.05 0.05 0.05</size>
            </box>
          </geometry>
        </visual>
        <visual name='base_footprint_fixed_joint_lump__lidar_visual_3'>
          <pose>0.28 0 0.075 0 0 -1.57</pose>
          <geometry>
            <cylinder>
              <length>0.015</length>
              <radius>0.025</radius>
            </cylinder>
          </geometry>
          <material>
            <script>
              <name>Gazebo/Blue</name>
              <uri>file://media/materials/scripts/gazebo.material</uri>
            </script>
          </material>
        </visual>
        <self_collide>1</self_collide>
        <gravity>1</gravity>
        <sensor name='camera1' type='camera'>
          <visualize>0</visualize>
          <update_rate>30</update_rate>
          <camera name='head'>
            <horizontal_fov>1.39626</horizontal_fov>
            <image>
              <width>800</width>
              <height>800</height>
              <format>R8G8B8</format>
            </image>
            <clip>
              <near>0.02</near>
              <far>300</far>
            </clip>
          </camera>
          <plugin name='camera_controller' filename='libgazebo_ros_camera.so'>
            <alwaysOn>1</alwaysOn>
            <updateRate>60.0</updateRate>
            <cameraName>/camera1</cameraName>
            <imageTopicName>image_raw</imageTopicName>
            <cameraInfoTopicName>info_camera</cameraInfoTopicName>
            <frameName>camera</frameName>
            <hackBaseline>0.07</hackBaseline>
            <robotNamespace>/</robotNamespace>
          </plugin>
          <pose>0.295 0 0.54 0 -0 0</pose>
        </sensor>
        <gravity>1</gravity>
        <sensor name='imu_sensor' type='imu'>
          <imu>
            <angular_velocity>
              <x>
                <noise type='gaussian'>
                  <mean>0</mean>
                  <stddev>0.0002</stddev>
                  <bias_mean>7.5e-06</bias_mean>
                  <bias_stddev>8e-07</bias_stddev>
                </noise>
              </x>
              <y>
                <noise type='gaussian'>
                  <mean>0</mean>
                  <stddev>0.0002</stddev>
                  <bias_mean>7.5e-06</bias_mean>
                  <bias_stddev>8e-07</bias_stddev>
                </noise>
              </y>
              <z>
                <noise type='gaussian'>
                  <mean>0</mean>
                  <stddev>0.0002</stddev>
                  <bias_mean>7.5e-06</bias_mean>
                  <bias_stddev>8e-07</bias_stddev>
                </noise>
              </z>
            </angular_velocity>
            <linear_acceleration>
              <x>
                <noise type='gaussian'>
                  <mean>0</mean>
                  <stddev>0.017</stddev>
                  <bias_mean>0.1</bias_mean>
                  <bias_stddev>0.001</bias_stddev>
                </noise>
              </x>
              <y>
                <noise type='gaussian'>
                  <mean>0</mean>
                  <stddev>0.017</stddev>
                  <bias_mean>0.1</bias_mean>
                  <bias_stddev>0.001</bias_stddev>
                </noise>
              </y>
              <z>
                <noise type='gaussian'>
                  <mean>0</mean>
                  <stddev>0.017</stddev>
                  <bias_mean>0.1</bias_mean>
                  <bias_stddev>0.001</bias_stddev>
                </noise>
              </z>
            </linear_acceleration>
          </imu>
          <always_on>1</always_on>
          <update_rate>100</update_rate>
          <visualize>1</visualize>
          <topic>imu</topic>
          <plugin name='imu_plugin' filename='libgazebo_ros_imu_sensor.so'>
            <topicName>imu</topicName>
            <bodyName>imu_link</bodyName>
            <updateRateHZ>10.0</updateRateHZ>
            <gaussianNoise>0.0</gaussianNoise>
            <xyzOffset>0 0 0</xyzOffset>
            <rpyOffset>0 0 0</rpyOffset>
            <frameName>imu_link</frameName>
            <initial_orientation_as_reference>1</initial_orientation_as_reference>
            <robotNamespace>/</robotNamespace>
          </plugin>
          <pose>0 0 0.08 0 -0 0</pose>
        </sensor>
        <sensor name='lidar' type='ray'>
          <always_on>1</always_on>
          <visualize>1</visualize>
          <update_rate>30</update_rate>
          <plugin name='scan' filename='libgazebo_ros_laser.so'>
            <topicName>/lidar_topic</topicName>
            <outputType>sensor_msgs/LaserScan</outputType>
            <frameName>lidar</frameName>
            <robotNamespace>/</robotNamespace>
          </plugin>
          <ray>
            <scan>
              <horizontal>
                <samples>720</samples>
                <resolution>1</resolution>
                <min_angle>0</min_angle>
                <max_angle>6.2832</max_angle>
              </horizontal>
              <vertical>
                <samples>1</samples>
                <min_angle>0</min_angle>
                <max_angle>0</max_angle>
              </vertical>
            </scan>
            <range>
              <min>0.58</min>
              <max>3.5</max>
              <resolution>0.015</resolution>
            </range>
          </ray>
          <pose>0.28 0 0.075 0 0 -1.57</pose>
        </sensor>
        <enable_wind>0</enable_wind>
        <kinematic>0</kinematic>
      </link>
      <joint name='Revolute 13' type='revolute'>
        <pose relative_to='base_footprint'>0.19 0.18 0.056794 0 -0 0</pose>
        <parent>base_footprint</parent>
        <child>wheel_4_1</child>
        <axis>
          <xyz>0 1 0</xyz>
          <limit>
            <lower>-1e+16</lower>
            <upper>1e+16</upper>
          </limit>
          <dynamics>
            <spring_reference>0</spring_reference>
            <spring_stiffness>0</spring_stiffness>
          </dynamics>
        </axis>
      </joint>
      <link name='wheel_4_1'>
        <pose relative_to='Revolute 13'>0 0 0 0 -0 0</pose>
        <inertial>
          <pose>0 0.013 0 0 -0 0</pose>
          <mass>1.603</mass>
          <inertia>
            <ixx>0.001092</ixx>
            <ixy>0</ixy>
            <ixz>0</ixz>
            <iyy>0.002004</iyy>
            <iyz>0</iyz>
            <izz>0.001092</izz>
          </inertia>
        </inertial>
        <collision name='wheel_4_1_collision'>
          <pose>-0.19 -0.18 -0.056794 0 -0 0</pose>
          <geometry>
            <mesh>
              <scale>0.001 0.001 0.001</scale>
              <uri>/home/aravs2/catkin_ws/src/server_bot/meshes/wheel_4_1.stl</uri>
            </mesh>
          </geometry>
          <surface>
            <contact>
              <ode/>
            </contact>
            <friction>
              <ode>
                <mu>0.2</mu>
                <mu2>0.2</mu2>
              </ode>
              <torsional>
                <ode/>
              </torsional>
            </friction>
            <bounce/>
          </surface>
          <max_contacts>10</max_contacts>
        </collision>
        <visual name='wheel_4_1_visual'>
          <pose>-0.19 -0.18 -0.056794 0 -0 0</pose>
          <geometry>
            <mesh>
              <scale>0.001 0.001 0.001</scale>
              <uri>/home/aravs2/catkin_ws/src/server_bot/meshes/wheel_4_1.stl</uri>
            </mesh>
          </geometry>
          <material>
            <script>
              <name>Gazebo/Silver</name>
              <uri>file://media/materials/scripts/gazebo.material</uri>
            </script>
          </material>
        </visual>
        <self_collide>1</self_collide>
        <enable_wind>0</enable_wind>
        <kinematic>0</kinematic>
      </link>
      <joint name='Revolute 14' type='revolute'>
        <pose relative_to='base_footprint'>-0.19 0.18 0.056794 0 -0 0</pose>
        <parent>base_footprint</parent>
        <child>wheel_3_1</child>
        <axis>
          <xyz>0 1 0</xyz>
          <limit>
            <lower>-1e+16</lower>
            <upper>1e+16</upper>
          </limit>
          <dynamics>
            <spring_reference>0</spring_reference>
            <spring_stiffness>0</spring_stiffness>
          </dynamics>
        </axis>
      </joint>
      <link name='wheel_3_1'>
        <pose relative_to='Revolute 14'>0 0 0 0 -0 0</pose>
        <inertial>
          <pose>0 0.013 0 0 -0 0</pose>
          <mass>1.603</mass>
          <inertia>
            <ixx>0.001092</ixx>
            <ixy>0</ixy>
            <ixz>0</ixz>
            <iyy>0.002004</iyy>
            <iyz>0</iyz>
            <izz>0.001092</izz>
          </inertia>
        </inertial>
        <collision name='wheel_3_1_collision'>
          <pose>0.19 -0.18 -0.056794 0 -0 0</pose>
          <geometry>
            <mesh>
              <scale>0.001 0.001 0.001</scale>
              <uri>/home/aravs2/catkin_ws/src/server_bot/meshes/wheel_3_1.stl</uri>
            </mesh>
          </geometry>
          <surface>
            <contact>
              <ode/>
            </contact>
            <friction>
              <ode>
                <mu>0.2</mu>
                <mu2>0.2</mu2>
              </ode>
              <torsional>
                <ode/>
              </torsional>
            </friction>
            <bounce/>
          </surface>
          <max_contacts>10</max_contacts>
        </collision>
        <visual name='wheel_3_1_visual'>
          <pose>0.19 -0.18 -0.056794 0 -0 0</pose>
          <geometry>
            <mesh>
              <scale>0.001 0.001 0.001</scale>
              <uri>/home/aravs2/catkin_ws/src/server_bot/meshes/wheel_3_1.stl</uri>
            </mesh>
          </geometry>
          <material>
            <script>
              <name>Gazebo/Silver</name>
              <uri>file://media/materials/scripts/gazebo.material</uri>
            </script>
          </material>
        </visual>
        <self_collide>1</self_collide>
        <enable_wind>0</enable_wind>
        <kinematic>0</kinematic>
      </link>
      <joint name='Revolute 15' type='revolute'>
        <pose relative_to='base_footprint'>-0.19 -0.18 0.056794 3.14 -0 0</pose>
        <parent>base_footprint</parent>
        <child>wheel_1_1</child>
        <axis>
          <xyz>0 -1 0</xyz>
          <limit>
            <lower>-1e+16</lower>
            <upper>1e+16</upper>
          </limit>
          <dynamics>
            <spring_reference>0</spring_reference>
            <spring_stiffness>0</spring_stiffness>
          </dynamics>
        </axis>
      </joint>
      <link name='wheel_1_1'>
        <pose relative_to='Revolute 15'>0 0 0 0 -0 0</pose>
        <inertial>
          <pose>-0 -0.013 0 0 -0 0</pose>
          <mass>1.603</mass>
          <inertia>
            <ixx>0.001092</ixx>
            <ixy>0</ixy>
            <ixz>0</ixz>
            <iyy>0.002004</iyy>
            <iyz>0</iyz>
            <izz>0.001092</izz>
          </inertia>
        </inertial>
        <collision name='wheel_1_1_collision'>
          <pose>0.19 0.18 -0.056794 0 -0 0</pose>
          <geometry>
            <mesh>
              <scale>0.001 0.001 0.001</scale>
              <uri>/home/aravs2/catkin_ws/src/server_bot/meshes/wheel_1_1.stl</uri>
            </mesh>
          </geometry>
          <surface>
            <contact>
              <ode/>
            </contact>
            <friction>
              <ode>
                <mu>0.2</mu>
                <mu2>0.2</mu2>
              </ode>
              <torsional>
                <ode/>
              </torsional>
            </friction>
            <bounce/>
          </surface>
          <max_contacts>10</max_contacts>
        </collision>
        <visual name='wheel_1_1_visual'>
          <pose>0.19 0.18 -0.056794 0 -0 0</pose>
          <geometry>
            <mesh>
              <scale>0.001 0.001 0.001</scale>
              <uri>/home/aravs2/catkin_ws/src/server_bot/meshes/wheel_1_1.stl</uri>
            </mesh>
          </geometry>
          <material>
            <script>
              <name>Gazebo/Silver</name>
              <uri>file://media/materials/scripts/gazebo.material</uri>
            </script>
          </material>
        </visual>
        <self_collide>1</self_collide>
        <enable_wind>0</enable_wind>
        <kinematic>0</kinematic>
      </link>
      <joint name='Revolute 16' type='revolute'>
        <pose relative_to='base_footprint'>0.19 -0.18 0.056794 3.14 -0 0</pose>
        <parent>base_footprint</parent>
        <child>wheel_2_1</child>
        <axis>
          <xyz>0 -1 0</xyz>
          <limit>
            <lower>-1e+16</lower>
            <upper>1e+16</upper>
          </limit>
          <dynamics>
            <spring_reference>0</spring_reference>
            <spring_stiffness>0</spring_stiffness>
          </dynamics>
        </axis>
      </joint>
      <link name='wheel_2_1'>
        <pose relative_to='Revolute 16'>0 0 0 0 -0 0</pose>
        <inertial>
          <pose>-0 -0.013 0 0 -0 0</pose>
          <mass>1.603</mass>
          <inertia>
            <ixx>0.001092</ixx>
            <ixy>0</ixy>
            <ixz>0</ixz>
            <iyy>0.002004</iyy>
            <iyz>0</iyz>
            <izz>0.001092</izz>
          </inertia>
        </inertial>
        <collision name='wheel_2_1_collision'>
          <pose>-0.19 0.18 -0.056794 0 -0 0</pose>
          <geometry>
            <mesh>
              <scale>0.001 0.001 0.001</scale>
              <uri>/home/aravs2/catkin_ws/src/server_bot/meshes/wheel_2_1.stl</uri>
            </mesh>
          </geometry>
          <surface>
            <contact>
              <ode/>
            </contact>
            <friction>
              <ode>
                <mu>0.2</mu>
                <mu2>0.2</mu2>
              </ode>
              <torsional>
                <ode/>
              </torsional>
            </friction>
            <bounce/>
          </surface>
          <max_contacts>10</max_contacts>
        </collision>
        <visual name='wheel_2_1_visual'>
          <pose>-0.19 0.18 -0.056794 0 -0 0</pose>
          <geometry>
            <mesh>
              <scale>0.001 0.001 0.001</scale>
              <uri>/home/aravs2/catkin_ws/src/server_bot/meshes/wheel_2_1.stl</uri>
            </mesh>
          </geometry>
          <material>
            <script>
              <name>Gazebo/Silver</name>
              <uri>file://media/materials/scripts/gazebo.material</uri>
            </script>
          </material>
        </visual>
        <self_collide>1</self_collide>
        <enable_wind>0</enable_wind>
        <kinematic>0</kinematic>
      </link>
      <plugin name='control' filename='libgazebo_ros_control.so'>
        <robotNamespace>/</robotNamespace>
      </plugin>
      <static>0</static>
      <plugin name='skid_steer_drive_controller' filename='libgazebo_ros_skid_steer_drive.so'>
        <updateRate>15.0</updateRate>
        <robotNamespace>/</robotNamespace>
        <rightFrontJoint>Revolute 16</rightFrontJoint>
        <leftFrontJoint>Revolute 13</leftFrontJoint>
        <rightRearJoint>Revolute 15</rightRearJoint>
        <leftRearJoint>Revolute 14</leftRearJoint>
        <wheelSeparation>0.4</wheelSeparation>
        <wheelDiameter>0.215</wheelDiameter>
        <robotBaseFrame>base_footprint</robotBaseFrame>
        <torque>40</torque>
        <topicName>cmd_vel</topicName>
        <broadcastTF>1</broadcastTF>
        <publishOdomTF>1</publishOdomTF>
        <publishOdom>1</publishOdom>
      </plugin>
      <pose>0 0 0 0 -0 0</pose>
    </model>
    <state world_name='default'>
      <sim_time>166 33000000</sim_time>
      <real_time>167 669824394</real_time>
      <wall_time>1711653261 14725729</wall_time>
      <iterations>166033</iterations>
      <model name='ground_plane'>
        <pose>0 0 0 0 -0 0</pose>
        <scale>1 1 1</scale>
        <link name='link'>
          <pose>0 0 0 0 -0 0</pose>
          <velocity>0 0 0 0 -0 0</velocity>
          <acceleration>0 0 0 0 -0 0</acceleration>
          <wrench>0 0 0 0 -0 0</wrench>
        </link>
      </model>
      <model name='turtlebot_new_world'>
        <pose>0 0 0 0 -0 0</pose>
        <scale>1 1 1</scale>
        <link name='ros_symbol::symbol'>
          <pose>0 0 0 0 -0 0</pose>
          <velocity>0 0 0 0 -0 0</velocity>
          <acceleration>0 0 0 0 -0 0</acceleration>
          <wrench>0 0 0 0 -0 0</wrench>
        </link>
      </model>
      <model name='urdf_base'>
        <pose>0.605108 1.92581 -0.006795 -0.000229 -2.5e-05 0.01937</pose>
        <scale>1 1 1</scale>
        <link name='base_footprint'>
          <pose>0.605108 1.92581 -0.006795 -0.000229 -2.5e-05 0.01937</pose>
          <velocity>-0.000755 -0.000482 0.000119 -0.008815 0.008635 -0.00054</velocity>
          <acceleration>2.29048 2.13992 0.398986 -1.83589 -1.53313 -1.5044</acceleration>
          <wrench>46.0062 42.982 8.01396 0 -0 0</wrench>
        </link>
        <link name='wheel_1_1'>
          <pose>0.41863 1.74218 0.050042 3.13431 1.31852 0.012312</pose>
          <velocity>-6e-06 0.000407 0.00468 -0.008149 0.00041 -0.000806</velocity>
          <acceleration>0.930961 0.003872 9.15356 -0.564525 0.492166 -1.98788</acceleration>
          <wrench>1.49233 0.006207 14.6731 0 -0 0</wrench>
        </link>
        <link name='wheel_2_1'>
          <pose>0.798557 1.74954 0.050045 3.12411 1.46641 0.001984</pose>
          <velocity>-0.000367 -6.5e-05 -0.000121 -0.008815 0.00864 -0.000498</velocity>
          <acceleration>0.180019 0.11196 -0.466256 1.53221 -0.123205 1.7976</acceleration>
          <wrench>0.28857 0.179472 -0.747409 0 -0 0</wrench>
        </link>
        <link name='wheel_3_1'>
          <pose>0.411656 2.10211 0.049953 -0.000252 -0.429158 0.019475</pose>
          <velocity>-0.000165 0.000131 0.000232 -0.008815 0.008632 -0.000542</velocity>
          <acceleration>-0.389092 -0.567729 0.25647 -1.60548 -1.42887 -1.45433</acceleration>
          <wrench>-0.623715 -0.91007 0.411121 0 -0 0</wrench>
        </link>
        <link name='wheel_4_1'>
          <pose>0.791583 2.10947 0.049967 -0.000245 -0.34391 0.019454</pose>
          <velocity>0.00017 0.000184 -0.004231 -0.008254 0.008644 -0.000825</velocity>
          <acceleration>0.268552 0.590553 -8.65853 -0.458239 -0.430163 -2.02133</acceleration>
          <wrench>0.430489 0.946656 -13.8796 0 -0 0</wrench>
        </link>
      </model>
      <light name='sun'>
        <pose>0 0 10 0 -0 0</pose>
      </light>
    </state>
  </world>
</sdf>
